Time slot   0
ld_routine
        Loaded a process at input/proc/f5, PID: 1 PRIO: 1

Time slot   1
        CPU 0: Dispatched process  1

Time slot   2
        CPU 0: Put process  1 to run queue
        CPU 0: Dispatched process  1
        Loaded a process at input/proc/f5, PID: 2 PRIO: 1

Time slot   3
        CPU 0: Put process  1 to run queue
        CPU 0: Dispatched process  2

Time slot   4
        CPU 0: Put process  2 to run queue
        CPU 0: Dispatched process  1
        Loaded a process at input/proc/f5, PID: 3 PRIO: 1

Time slot   5
        CPU 0: Put process  1 to run queue
        CPU 0: Dispatched process  2

Time slot   6
        Loaded a process at input/proc/f5, PID: 4 PRIO: 1
        CPU 0: Put process  2 to run queue
        CPU 0: Dispatched process  3

Time slot   7
        CPU 0: Put process  3 to run queue
        CPU 0: Dispatched process  1

Time slot   8
        CPU 0: Put process  1 to run queue
        CPU 0: Dispatched process  4

Time slot   9
        CPU 0: Put process  4 to run queue
        CPU 0: Dispatched process  2

Time slot  10
        CPU 0: Put process  2 to run queue
        CPU 0: Dispatched process  3

Time slot  11
        CPU 0: Put process  3 to run queue
        CPU 0: Dispatched process  1

Time slot  12
        CPU 0: Processed  1 has finished
        CPU 0: Dispatched process  4

Time slot  13
        CPU 0: Put process  4 to run queue
        CPU 0: Dispatched process  2

Time slot  14
        CPU 0: Put process  2 to run queue
        CPU 0: Dispatched process  3

Time slot  15
        CPU 0: Put process  3 to run queue
        CPU 0: Dispatched process  4

Time slot  16
        CPU 0: Put process  4 to run queue
        CPU 0: Dispatched process  2

Time slot  17
        CPU 0: Processed  2 has finished
        CPU 0: Dispatched process  3

Time slot  18
        CPU 0: Put process  3 to run queue
        CPU 0: Dispatched process  4

Time slot  19
        CPU 0: Put process  4 to run queue
        CPU 0: Dispatched process  3

Time slot  20
        CPU 0: Processed  3 has finished
        CPU 0: Dispatched process  4

Time slot  21
        CPU 0: Processed  4 has finished
        CPU 0 stopped
